Workbook

Sheet Leia-me
A1: Catálogo de itens — App de organização financeira do casamento (v2, rascunho)
A3: O que é | B3: Primeira versão do catálogo que gera o plano do casal: itens com custo, em que estilo cada um aparece, se entra no checklist e o prazo de decisão. Serve para revisão e, depois, para virar a tabela de templates no Supabase.
A4: Abas | B4: Catálogo: a lista de itens (esta é a base que será importada). Simulador: informe a data do casamento, o estilo e se é destination, e veja a lista e os prazos ajustados. Cenários: como o prazo muda conforme o tempo disponível.
A5: Cores | B5: Texto azul com fundo amarelo = campo que você edita. Texto preto = fórmula, não editar.
A6: Estilo e nível | B6: Cada item tem nível 1, 2 ou 3. 'Só o necessário' mostra o nível 1; 'Minimalista' mostra os níveis 1 e 2; 'Completo' mostra os níveis 1, 2 e 3. Nível 1 = Básico; níveis 2 e 3 = Adicional.
A7: Destination | B7: Itens marcados 'Só destination' só aparecem quando o casal escolhe destination wedding. Nesta versão são 5 itens.
A8: Checklist | B8: O checklist enxuto usa só os itens marcados como Essencial que estão no plano do casal. Nesta versão são 24 essenciais no total (de 19 a 24 por casal, conforme estilo e destination).
A9: Prazo padrão | B9: Em meses antes do casamento, para quem tem 12 meses ou mais. Vem do fim da janela da planilha de referência (ex.: '10 a 12 meses' vira 10). Itens marcados como estimativa própria não constam na referência. Valor negativo = meses depois do casamento.
A10: Ajuste do prazo | B10: Prazo ajustado = prazo padrão x fator. Fator = menor valor entre 1 e (meses disponíveis / janela padrão de 12). Quem tem 12 meses ou mais usa os prazos padrão; quem tem menos tem todos os prazos encurtados na mesma proporção. Prazos negativos (depois do casamento) não são encurtados. Data limite = data do casamento menos o prazo ajustado.
A11: Limite da regra | B11: Com menos de 4 meses disponíveis o Simulador mostra um aviso: os prazos ficam muito próximos entre si e vale priorizar só os essenciais.
A12: Fonte e uso | B12: A estrutura (grupos, ordem e janelas de prazo) foi derivada da Agenda de Tarefas do Casamentos.com.br, planilha enviada por Bruno. Nomes e observações dos itens são próprios; os textos da referência não foram copiados.
A13: Premissas a validar | B13: Nível de cada item, quais são essenciais (itens marcados 'Sugestão' foram sugeridos, não vêm da referência), as estimativas próprias e a regra de 'janela padrão de 12 meses'. Tudo isso é decisão de produto e pode mudar.

Sheet Catálogo
A1: id | B1: Categoria | C1: Item | D1: Nível (1 a 3) | E1: Tipo | F1: Essencial (checklist) | G1: Origem do essencial | H1: Destination | I1: Prazo padrão (meses antes) | J1: Origem do prazo | K1: Observação
A2: 1 | B2: Planejamento e documentos | C2: Reserva para imprevistos (5 a 10% do orçamento) | D2: 1 | E2: =IF(D2=1,"Básico","Adicional") -> Básico | F2: Sim | G2: Sugestão | H2: Todos | I2: 12 | J2: Estimativa própria (não consta na planilha de referência) | K2: Definir no início, junto com o orçamento
A3: 2 | B3: Planejamento e documentos | C3: Cerimonialista ou assessoria | D3: 1 | E3: =IF(D3=1,"Básico","Adicional") -> Básico | F3: Sim | G3: Sugestão | H3: Todos | I3: 10 | J3: Planilha de referência (10 a 12 meses) | K3: Decisão entre organizar sozinhos ou contratar
A4: 3 | B4: Cerimônia e música | C4: Local da cerimônia | D4: 1 | E4: =IF(D4=1,"Básico","Adicional") -> Básico | F4: Sim | G4: Sugestão | H4: Todos | I4: 10 | J4: Planilha de referência (10 a 12 meses) | K4: Pode ser o mesmo espaço da recepção
A5: 4 | B5: Cerimônia e música | C5: Celebrante ou juiz de paz | D5: 1 | E5: =IF(D5=1,"Básico","Adicional") -> Básico | F5: Sim | G5: Sugestão | H5: Todos | I5: 10 | J5: Planilha de referência (10 a 12 meses)
A6: 5 | B6: Festa e decoração | C6: Espaço da recepção | D6: 1 | E6: =IF(D6=1,"Básico","Adicional") -> Básico | F6: Sim | G6: Planilha | H6: Todos | I6: 10 | J6: Planilha de referência (10 a 12 meses)
A7: 6 | B7: Festa e decoração | C7: Buffet ou catering | D7: 1 | E7: =IF(D7=1,"Básico","Adicional") -> Básico | F7: Sim | G7: Planilha | H7: Todos | I7: 10 | J7: Planilha de referência (10 a 12 meses)
A8: 7 | B8: Festa e decoração | C8: Animação e atrações da festa | D8: 3 | E8: =IF(D8=1,"Básico","Adicional") -> Adicional | F8: Não | H8: Todos | I8: 10 | J8: Planilha de referência (10 a 12 meses)
A9: 8 | B9: Foto e vídeo | C9: Fotógrafo | D9: 1 | E9: =IF(D9=1,"Básico","Adicional") -> Básico | F9: Sim | G9: Planilha | H9: Todos | I9: 10 | J9: Planilha de referência (10 a 12 meses)
A10: 9 | B10: Foto e vídeo | C10: Filmagem | D10: 3 | E10: =IF(D10=1,"Básico","Adicional") -> Adicional | F10: Não | H10: Todos | I10: 10 | J10: Estimativa própria (não consta na planilha de referência) | K10: Sugestão: contratar junto com o fotógrafo
A11: 10 | B11: Cerimônia e música | C11: Música ou DJ da cerimônia | D11: 1 | E11: =IF(D11=1,"Básico","Adicional") -> Básico | F11: Sim | G11: Planilha | H11: Todos | I11: 10 | J11: Planilha de referência (10 a 12 meses) | K11: Na referência, 'músicos' é uma única linha essencial; aqui foi dividida em dois itens
A12: 11 | B12: Cerimônia e música | C12: Banda ou DJ da festa | D12: 1 | E12: =IF(D12=1,"Básico","Adicional") -> Básico | F12: Sim | G12: Planilha | H12: Todos | I12: 10 | J12: Planilha de referência (10 a 12 meses)
A13: 12 | B13: Convidados e convites | C13: Save the date | D13: 3 | E13: =IF(D13=1,"Básico","Adicional") -> Adicional | F13: Não | H13: Todos | I13: 10 | J13: Planilha de referência (10 a 12 meses)
A14: 13 | B14: Viagens e hospedagem | C14: Hospedagem dos convidados | D14: 1 | E14: =IF(D14=1,"Básico","Adicional") -> Básico | F14: Não | H14: Só destination | I14: 10 | J14: Planilha de referência (10 a 12 meses) | K14: Aparece só em destination wedding
A15: 14 | B15: Planejamento e documentos | C15: Visita técnica ao local | D15: 1 | E15: =IF(D15=1,"Básico","Adicional") -> Básico | F15: Sim | G15: Sugestão | H15: Só destination | I15: 10 | J15: Estimativa própria (não consta na planilha de referência) | K15: Aparece só em destination wedding
A16: 15 | B16: Viagens e hospedagem | C16: Passagens e documentos de viagem dos noivos | D16: 1 | E16: =IF(D16=1,"Básico","Adicional") -> Básico | F16: Não | H16: Só destination | I16: 10 | J16: Estimativa própria (não consta na planilha de referência) | K16: Aparece só em destination wedding
A17: 16 | B17: Planejamento e documentos | C17: Casamento civil: documentos e taxas | D17: 1 | E17: =IF(D17=1,"Básico","Adicional") -> Básico | F17: Sim | G17: Planilha | H17: Todos | I17: 7 | J17: Planilha de referência (7 a 9 meses) | K17: Marcar 'não se aplica' se não houver casamento civil
A18: 17 | B18: Planejamento e documentos | C18: Casamento religioso: documentos e taxas | D18: 1 | E18: =IF(D18=1,"Básico","Adicional") -> Básico | F18: Sim | G18: Planilha | H18: Todos | I18: 7 | J18: Planilha de referência (7 a 9 meses) | K18: Marcar 'não se aplica' se não houver cerimônia religiosa
A19: 18 | B19: Festa e decoração | C19: Estrutura, som e iluminação | D19: 2 | E19: =IF(D19=1,"Básico","Adicional") -> Adicional | F19: Não | H19: Todos | I19: 7 | J19: Estimativa própria (não consta na planilha de referência) | K19: Tenda, banheiros, gerador e afins conforme o local
A20: 19 | B20: Noivos e beleza | C20: Vestido de noiva | D20: 1 | E20: =IF(D20=1,"Básico","Adicional") -> Básico | F20: Sim | G20: Planilha | H20: Todos | I20: 7 | J20: Planilha de referência (7 a 9 meses) | K20: Inclui a decisão entre alugar e comprar
A21: 20 | B21: Viagens e hospedagem | C21: Hospedagem e deslocamento dos fornecedores | D21: 1 | E21: =IF(D21=1,"Básico","Adicional") -> Básico | F21: Não | H21: Só destination | I21: 7 | J21: Estimativa própria (não consta na planilha de referência) | K21: Aparece só em destination wedding
A22: 21 | B22: Planejamento e documentos | C22: Pacto antenupcial e regime de bens | D22: 3 | E22: =IF(D22=1,"Básico","Adicional") -> Adicional | F22: Não | H22: Todos | I22: 7 | J22: Estimativa própria (não consta na planilha de referência) | K22: Escritura em cartório, com custo próprio
A23: 22 | B23: Convidados e convites | C23: Lista de presentes e site do casamento | D23: 2 | E23: =IF(D23=1,"Básico","Adicional") -> Adicional | F23: Não | H23: Todos | I23: 7 | J23: Estimativa própria (não consta na planilha de referência) | K23: O site também serve para confirmação de presença
A24: 23 | B24: Foto e vídeo | C24: Ensaio pré-wedding | D24: 3 | E24: =IF(D24=1,"Básico","Adicional") -> Adicional | F24: Não | H24: Todos | I24: 7 | J24: Estimativa própria (não consta na planilha de referência) | K24: Sugestão: contratar junto com o fotógrafo
A25: 24 | B25: Viagens e hospedagem | C25: Passaporte, visto e seguro viagem | D25: 2 | E25: =IF(D25=1,"Básico","Adicional") -> Adicional | F25: Não | H25: Todos | I25: 7 | J25: Estimativa própria (não consta na planilha de referência) | K25: Passaporte e visto podem demorar meses
A26: 25 | B26: Planejamento e documentos | C26: Documentação do casamento no exterior (apostila, tradução) | D26: 1 | E26: =IF(D26=1,"Básico","Adicional") -> Básico | F26: Não | H26: Só destination | I26: 7 | J26: Estimativa própria (não consta na planilha de referência) | K26: Aparece só em destination wedding
A27: 26 | B27: Festa e decoração | C27: Bolo e doces | D27: 1 | E27: =IF(D27=1,"Básico","Adicional") -> Básico | F27: Não | H27: Todos | I27: 4 | J27: Planilha de referência (4 a 6 meses)
A28: 27 | B28: Festa e decoração | C28: Decoração e flores | D28: 1 | E28: =IF(D28=1,"Básico","Adicional") -> Básico | F28: Sim | G28: Planilha | H28: Todos | I28: 4 | J28: Planilha de referência (4 a 6 meses)
A29: 28 | B29: Convidados e convites | C29: Convites | D29: 1 | E29: =IF(D29=1,"Básico","Adicional") -> Básico | F29: Sim | G29: Planilha | H29: Todos | I29: 4 | J29: Planilha de referência (4 a 6 meses)
A30: 29 | B30: Noivos e beleza | C30: Traje do noivo | D30: 1 | E30: =IF(D30=1,"Básico","Adicional") -> Básico | F30: Sim | G30: Planilha | H30: Todos | I30: 4 | J30: Planilha de referência (4 a 6 meses)
A31: 30 | B31: Noivos e beleza | C31: Acessórios do noivo | D31: 2 | E31: =IF(D31=1,"Básico","Adicional") -> Adicional | F31: Não | H31: Todos | I31: 4 | J31: Planilha de referência (4 a 6 meses)
A32: 31 | B32: Viagens e hospedagem | C32: Transporte dos convidados | D32: 2 | E32: =IF(D32=1,"Básico","Adicional") -> Adicional | F32: Sim | G32: Planilha | H32: Todos | I32: 4 | J32: Planilha de referência (4 a 6 meses)
A33: 32 | B33: Viagens e hospedagem | C33: Lua de mel | D33: 2 | E33: =IF(D33=1,"Básico","Adicional") -> Adicional | F33: Sim | G33: Planilha | H33: Todos | I33: 4 | J33: Planilha de referência (4 a 6 meses) | K33: Reserva da viagem
A34: 33 | B34: Extras e festas do casal | C34: Festa e presentes de compromisso | D34: 3 | E34: =IF(D34=1,"Básico","Adicional") -> Adicional | F34: Não | H34: Todos | I34: 4 | J34: Planilha de referência (4 a 6 meses) | K34: Agrupa 2 linhas da referência em 1 item
A35: 34 | B35: Festa e decoração | C35: Bebidas e bar (open bar, bartender) | D35: 2 | E35: =IF(D35=1,"Básico","Adicional") -> Adicional | F35: Não | H35: Todos | I35: 4 | J35: Estimativa própria (não consta na planilha de referência) | K35: Muitas vezes contratado à parte do buffet
A36: 35 | B36: Festa e decoração | C36: Segurança, estacionamento e equipe de apoio | D36: 2 | E36: =IF(D36=1,"Básico","Adicional") -> Adicional | F36: Não | H36: Todos | I36: 4 | J36: Estimativa própria (não consta na planilha de referência) | K36: Manobrista, segurança, limpeza e recepcionistas
A37: 36 | B37: Extras e festas do casal | C37: Chá de panela ou chá bar | D37: 3 | E37: =IF(D37=1,"Básico","Adicional") -> Adicional | F37: Não | H37: Todos | I37: 4 | J37: Estimativa própria (não consta na planilha de referência)
A38: 37 | B38: Convidados e convites | C38: Papelaria complementar (menu, plaquinhas, mapa de mesas) | D38: 3 | E38: =IF(D38=1,"Básico","Adicional") -> Adicional | F38: Não | H38: Todos | I38: 4 | J38: Estimativa própria (não consta na planilha de referência)
A39: 38 | B39: Festa e decoração | C39: Espaço kids e recreação infantil | D39: 3 | E39: =IF(D39=1,"Básico","Adicional") -> Adicional | F39: Não | H39: Todos | I39: 4 | J39: Estimativa própria (não consta na planilha de referência)
A40: 39 | B40: Planejamento e documentos | C40: Seguro do evento | D40: 3 | E40: =IF(D40=1,"Básico","Adicional") -> Adicional | F40: Não | H40: Todos | I40: 4 | J40: Estimativa própria (não consta na planilha de referência)
...

Sheet Simulador
A1: Simulador de plano e prazos
A2: Altere os campos em azul com fundo amarelo (exemplo já preenchido).
A3: Hoje | B3: 46313
A4: Data do casamento | B4: 46557
A5: Estilo do grande dia | B5: Só o necessário
A6: Destination wedding? | B6: Não
A8: Meses disponíveis | B8: =(B4-B3)/30.4375 -> 8.0164271
A9: Janela padrão (meses) | B9: 12
A10: Fator de ajuste | B10: =MAX(0,MIN(1,B8/B9)) -> 0.66803559
A11: Nível do estilo | B11: =IF(B5="Completo",3,IF(B5="Minimalista",2,1)) -> 1
A12: Itens no plano | B12: =COUNTIF(C18:C71,"Sim") -> 20
A13: Itens no checklist | B13: =COUNTIF(D18:D71,"Sim") -> 19
A14: Aviso | B14: =IF(B8<=0,"Data do casamento já passou",IF(B8<4,"Prazo curto: priorize os essenciais",""))
A17: Item | B17: Categoria | C17: No plano? | D17: No checklist? | E17: Prazo padrão (meses antes) | F17: Prazo ajustado (meses antes) | G17: Data limite
A18: =Catálogo!C2 -> Reserva para imprevistos (5 a 10% do orçamento) | B18: =Catálogo!B2 -> Planejamento e documentos | C18: =IF(AND(Catálogo!D2<=$B$11,OR(Catálogo!H2="Todos",$B$6="Sim")),"Sim","Não") -> Sim | D18: =IF(AND(C18="Sim",Catálogo!F2="Sim"),"Sim","Não") -> Sim | E18: =Catálogo!I2 -> 12 | F18: =IF(C18="Sim",IF(E18<0,E18,E18*$B$10),"") -> 8.0164271 | G18: =IF(C18="Sim",$B$4-ROUND(F18*30.4375,0),"") -> 46313
A19: =Catálogo!C3 -> Cerimonialista ou assessoria | B19: =Catálogo!B3 -> Planejamento e documentos | C19: =IF(AND(Catálogo!D3<=$B$11,OR(Catálogo!H3="Todos",$B$6="Sim")),"Sim","Não") -> Sim | D19: =IF(AND(C19="Sim",Catálogo!F3="Sim"),"Sim","Não") -> Sim | E19: =Catálogo!I3 -> 10 | F19: =IF(C19="Sim",IF(E19<0,E19,E19*$B$10),"") -> 6.6803559 | G19: =IF(C19="Sim",$B$4-ROUND(F19*30.4375,0),"") -> 46354
A20: =Catálogo!C4 -> Local da cerimônia | B20: =Catálogo!B4 -> Cerimônia e música | C20: =IF(AND(Catálogo!D4<=$B$11,OR(Catálogo!H4="Todos",$B$6="Sim")),"Sim","Não") -> Sim | D20: =IF(AND(C20="Sim",Catálogo!F4="Sim"),"Sim","Não") -> Sim | E20: =Catálogo!I4 -> 10 | F20: =IF(C20="Sim",IF(E20<0,E20,E20*$B$10),"") -> 6.6803559 | G20: =IF(C20="Sim",$B$4-ROUND(F20*30.4375,0),"") -> 46354
A21: =Catálogo!C5 -> Celebrante ou juiz de paz | B21: =Catálogo!B5 -> Cerimônia e música | C21: =IF(AND(Catálogo!D5<=$B$11,OR(Catálogo!H5="Todos",$B$6="Sim")),"Sim","Não") -> Sim | D21: =IF(AND(C21="Sim",Catálogo!F5="Sim"),"Sim","Não") -> Sim | E21: =Catálogo!I5 -> 10 | F21: =IF(C21="Sim",IF(E21<0,E21,E21*$B$10),"") -> 6.6803559 | G21: =IF(C21="Sim",$B$4-ROUND(F21*30.4375,0),"") -> 46354
A22: =Catálogo!C6 -> Espaço da recepção | B22: =Catálogo!B6 -> Festa e decoração | C22: =IF(AND(Catálogo!D6<=$B$11,OR(Catálogo!H6="Todos",$B$6="Sim")),"Sim","Não") -> Sim | D22: =IF(AND(C22="Sim",Catálogo!F6="Sim"),"Sim","Não") -> Sim | E22: =Catálogo!I6 -> 10 | F22: =IF(C22="Sim",IF(E22<0,E22,E22*$B$10),"") -> 6.6803559 | G22: =IF(C22="Sim",$B$4-ROUND(F22*30.4375,0),"") -> 46354
A23: =Catálogo!C7 -> Buffet ou catering | B23: =Catálogo!B7 -> Festa e decoração | C23: =IF(AND(Catálogo!D7<=$B$11,OR(Catálogo!H7="Todos",$B$6="Sim")),"Sim","Não") -> Sim | D23: =IF(AND(C23="Sim",Catálogo!F7="Sim"),"Sim","Não") -> Sim | E23: =Catálogo!I7 -> 10 | F23: =IF(C23="Sim",IF(E23<0,E23,E23*$B$10),"") -> 6.6803559 | G23: =IF(C23="Sim",$B$4-ROUND(F23*30.4375,0),"") -> 46354
A24: =Catálogo!C8 -> Animação e atrações da festa | B24: =Catálogo!B8 -> Festa e decoração | C24: =IF(AND(Catálogo!D8<=$B$11,OR(Catálogo!H8="Todos",$B$6="Sim")),"Sim","Não") -> Não | D24: =IF(AND(C24="Sim",Catálogo!F8="Sim"),"Sim","Não") -> Não | E24: =Catálogo!I8 -> 10 | F24: =IF(C24="Sim",IF(E24<0,E24,E24*$B$10),"") | G24: =IF(C24="Sim",$B$4-ROUND(F24*30.4375,0),"")
A25: =Catálogo!C9 -> Fotógrafo | B25: =Catálogo!B9 -> Foto e vídeo | C25: =IF(AND(Catálogo!D9<=$B$11,OR(Catálogo!H9="Todos",$B$6="Sim")),"Sim","Não") -> Sim | D25: =IF(AND(C25="Sim",Catálogo!F9="Sim"),"Sim","Não") -> Sim | E25: =Catálogo!I9 -> 10 | F25: =IF(C25="Sim",IF(E25<0,E25,E25*$B$10),"") -> 6.6803559 | G25: =IF(C25="Sim",$B$4-ROUND(F25*30.4375,0),"") -> 46354
A26: =Catálogo!C10 -> Filmagem | B26: =Catálogo!B10 -> Foto e vídeo | C26: =IF(AND(Catálogo!D10<=$B$11,OR(Catálogo!H10="Todos",$B$6="Sim")),"Sim","Não") -> Não | D26: =IF(AND(C26="Sim",Catálogo!F10="Sim"),"Sim","Não") -> Não | E26: =Catálogo!I10 -> 10 | F26: =IF(C26="Sim",IF(E26<0,E26,E26*$B$10),"") | G26: =IF(C26="Sim",$B$4-ROUND(F26*30.4375,0),"")
A27: =Catálogo!C11 -> Música ou DJ da cerimônia | B27: =Catálogo!B11 -> Cerimônia e música | C27: =IF(AND(Catálogo!D11<=$B$11,OR(Catálogo!H11="Todos",$B$6="Sim")),"Sim","Não") -> Sim | D27: =IF(AND(C27="Sim",Catálogo!F11="Sim"),"Sim","Não") -> Sim | E27: =Catálogo!I11 -> 10 | F27: =IF(C27="Sim",IF(E27<0,E27,E27*$B$10),"") -> 6.6803559 | G27: =IF(C27="Sim",$B$4-ROUND(F27*30.4375,0),"") -> 46354
A28: =Catálogo!C12 -> Banda ou DJ da festa | B28: =Catálogo!B12 -> Cerimônia e música | C28: =IF(AND(Catálogo!D12<=$B$11,OR(Catálogo!H12="Todos",$B$6="Sim")),"Sim","Não") -> Sim | D28: =IF(AND(C28="Sim",Catálogo!F12="Sim"),"Sim","Não") -> Sim | E28: =Catálogo!I12 -> 10 | F28: =IF(C28="Sim",IF(E28<0,E28,E28*$B$10),"") -> 6.6803559 | G28: =IF(C28="Sim",$B$4-ROUND(F28*30.4375,0),"") -> 46354
A29: =Catálogo!C13 -> Save the date | B29: =Catálogo!B13 -> Convidados e convites | C29: =IF(AND(Catálogo!D13<=$B$11,OR(Catálogo!H13="Todos",$B$6="Sim")),"Sim","Não") -> Não | D29: =IF(AND(C29="Sim",Catálogo!F13="Sim"),"Sim","Não") -> Não | E29: =Catálogo!I13 -> 10 | F29: =IF(C29="Sim",IF(E29<0,E29,E29*$B$10),"") | G29: =IF(C29="Sim",$B$4-ROUND(F29*30.4375,0),"")
... A71: =Catálogo!C55 -> Álbum e entrega do material | B71: =Catálogo!B55 -> Foto e vídeo | C71: =IF(AND(Catálogo!D55<=$B$11,OR(Catálogo!H55="Todos",$B$6="Sim")),"Sim","Não") -> Não | D71: =IF(AND(C71="Sim",Catálogo!F55="Sim"),"Sim","Não") -> Não | E71: =Catálogo!I55 -> -2 | F71: =IF(C71="Sim",IF(E71<0,E71,E71*$B$10),"") | G71: =IF(C71="Sim",$B$4-ROUND(F71*30.4375,0),"")

Sheet Cenários
A1: Quando vence cada prazo conforme o tempo disponível
A2: Valores em meses a partir de hoje. Fórmula: meses disponíveis - prazo padrão x fator (fator = menor valor entre 1 e meses disponíveis / janela padrão).
B3: Meses disponíveis até o casamento
A4: Prazo padrão (meses antes) | B4: 18 | C4: 12 | D4: 9 | E4: 6 | F4: 4 | G4: 3
A5: 10 | B5: =B$4-$A5*MAX(0,MIN(1,B$4/Simulador!$B$9)) -> 8 | C5: =C$4-$A5*MAX(0,MIN(1,C$4/Simulador!$B$9)) -> 2 | D5: =D$4-$A5*MAX(0,MIN(1,D$4/Simulador!$B$9)) -> 1.5 | E5: =E$4-$A5*MAX(0,MIN(1,E$4/Simulador!$B$9)) -> 1 | F5: =F$4-$A5*MAX(0,MIN(1,F$4/Simulador!$B$9)) -> 0.66666667 | G5: =G$4-$A5*MAX(0,MIN(1,G$4/Simulador!$B$9)) -> 0.5
A6: 7 | B6: =B$4-$A6*MAX(0,MIN(1,B$4/Simulador!$B$9)) -> 11 | C6: =C$4-$A6*MAX(0,MIN(1,C$4/Simulador!$B$9)) -> 5 | D6: =D$4-$A6*MAX(0,MIN(1,D$4/Simulador!$B$9)) -> 3.75 | E6: =E$4-$A6*MAX(0,MIN(1,E$4/Simulador!$B$9)) -> 2.5 | F6: =F$4-$A6*MAX(0,MIN(1,F$4/Simulador!$B$9)) -> 1.6666667 | G6: =G$4-$A6*MAX(0,MIN(1,G$4/Simulador!$B$9)) -> 1.25
A7: 4 | B7: =B$4-$A7*MAX(0,MIN(1,B$4/Simulador!$B$9)) -> 14 | C7: =C$4-$A7*MAX(0,MIN(1,C$4/Simulador!$B$9)) -> 8 | D7: =D$4-$A7*MAX(0,MIN(1,D$4/Simulador!$B$9)) -> 6 | E7: =E$4-$A7*MAX(0,MIN(1,E$4/Simulador!$B$9)) -> 4 | F7: =F$4-$A7*MAX(0,MIN(1,F$4/Simulador!$B$9)) -> 2.6666667 | G7: =G$4-$A7*MAX(0,MIN(1,G$4/Simulador!$B$9)) -> 2
A8: 2 | B8: =B$4-$A8*MAX(0,MIN(1,B$4/Simulador!$B$9)) -> 16 | C8: =C$4-$A8*MAX(0,MIN(1,C$4/Simulador!$B$9)) -> 10 | D8: =D$4-$A8*MAX(0,MIN(1,D$4/Simulador!$B$9)) -> 7.5 | E8: =E$4-$A8*MAX(0,MIN(1,E$4/Simulador!$B$9)) -> 5 | F8: =F$4-$A8*MAX(0,MIN(1,F$4/Simulador!$B$9)) -> 3.3333333 | G8: =G$4-$A8*MAX(0,MIN(1,G$4/Simulador!$B$9)) -> 2.5
A10: Exemplo com os valores iniciais: com 18 meses, o prazo de 10 meses antes vence daqui a 8 meses. Com 6 meses, esse mesmo prazo vence daqui a 1 mês, e os demais se espremem na mesma proporção.
